<?xml version="1.0"?>
<!--
    - Base      : kobuki
    - Stacks    : hexagons
    - 3d Sensor : kinect
-->    
<robot name="turtlebot" xmlns:xacro="http://ros.org/wiki/xacro">

  <xacro:include filename="$(find turtlebot_description)/urdf/turtlebot_library.urdf.xacro" />
  
  <kobuki/>
  <stack_hexagons parent="base_link"/>
  <sensor_kinect  parent="base_link"/>


    <joint name="fixed" type="revolute">
      <parent link="base_link"/>
      <child link="link1"/>
    </joint>

<!-- Base Link -->
<link name="link1">
  <collision>
    <origin xyz="0 0 5" rpy="0 0 0"/>
    <geometry>
      <box size="10 10 10"/>
    </geometry>
  </collision>

  <visual>
    <origin xyz="0 0 5" rpy="0 0 0"/>
    <geometry>
      <box size="10 10 10"/>
    </geometry>
    <material name="orange"/>
  </visual>

  <inertial>
    <origin xyz="0 0 1" rpy="0 0 0"/>
    <mass value="1"/>
    <inertia
      ixx="1.0" ixy="0.0" ixz="0.0"
      iyy="1.0" iyz="0.0"
      izz="1.0"/>
  </inertial>
</link>

</robot>
